2018-11-19 11:15:44,644 INFO: Microblog startup [in /Users/huiji/Desktop/mine/python/microblog/app/__init__.py:45]
2018-11-19 11:19:51,358 INFO: Microblog startup [in /Users/huiji/Desktop/mine/python/microblog/app/__init__.py:47]
2018-11-19 11:32:56,244 INFO: Microblog startup [in /Users/huiji/Desktop/mine/python/microblog/app/__init__.py:47]
2018-11-19 11:39:00,927 INFO: Microblog startup [in /Users/huiji/Desktop/mine/python/microblog/app/__init__.py:47]
2018-11-19 11:42:13,714 INFO: Microblog startup [in /Users/huiji/Desktop/mine/python/microblog/app/__init__.py:47]
2018-11-19 14:44:56,311 INFO: Microblog startup [in /Users/huiji/Desktop/mine/python/microblog/app/__init__.py:47]
2018-11-19 14:55:07,091 INFO: Microblog startup [in /Users/huiji/Desktop/mine/python/microblog/app/__init__.py:47]
2018-11-21 19:16:34,832 INFO: Microblog startup [in /Users/huiji/Desktop/mine/python/microblog/app/__init__.py:47]
2018-11-21 19:19:30,424 INFO: Microblog startup [in /Users/huiji/Desktop/mine/python/microblog/app/__init__.py:47]
2018-11-21 19:21:39,922 INFO: Microblog startup [in /Users/huiji/Desktop/mine/python/microblog/app/__init__.py:47]
2018-11-21 19:22:51,869 INFO: Microblog startup [in /Users/huiji/Desktop/mine/python/microblog/app/__init__.py:47]
2018-11-21 19:23:03,660 ERROR: Exception on /reset_password_request [POST] [in /Users/huiji/Desktop/mine/python/microblog/venv/lib/python3.7/site-packages/flask/app.py:1761]
Traceback (most recent call last):
  File "/Users/huiji/Desktop/mine/python/microblog/venv/lib/python3.7/site-packages/flask/app.py", line 2292, in wsgi_app
    response = self.full_dispatch_request()
  File "/Users/huiji/Desktop/mine/python/microblog/venv/lib/python3.7/site-packages/flask/app.py", line 1815, in full_dispatch_request
    rv = self.handle_user_exception(e)
  File "/Users/huiji/Desktop/mine/python/microblog/venv/lib/python3.7/site-packages/flask/app.py", line 1718, in handle_user_exception
    reraise(exc_type, exc_value, tb)
  File "/Users/huiji/Desktop/mine/python/microblog/venv/lib/python3.7/site-packages/flask/_compat.py", line 35, in reraise
    raise value
  File "/Users/huiji/Desktop/mine/python/microblog/venv/lib/python3.7/site-packages/flask/app.py", line 1813, in full_dispatch_request
    rv = self.dispatch_request()
  File "/Users/huiji/Desktop/mine/python/microblog/venv/lib/python3.7/site-packages/flask/app.py", line 1799, in dispatch_request
    return self.view_functions[rule.endpoint](**req.view_args)
  File "/Users/huiji/Desktop/mine/python/microblog/app/routes.py", line 151, in reset_password_request
    send_password_reset_email(user)
  File "/Users/huiji/Desktop/mine/python/microblog/app/email.py", line 19, in send_password_reset_email
    token = user.get_reset_password_token()
  File "/Users/huiji/Desktop/mine/python/microblog/app/models.py", line 61, in get_reset_password_token
    app.config['SECRET_KEY'], aloorithm='HS256').decode('utf-8')
TypeError: encode() got an unexpected keyword argument 'aloorithm'
2018-11-21 19:23:30,214 INFO: Microblog startup [in /Users/huiji/Desktop/mine/python/microblog/app/__init__.py:47]
2018-11-21 19:23:44,121 ERROR: Exception on /reset_password_request [POST] [in /Users/huiji/Desktop/mine/python/microblog/venv/lib/python3.7/site-packages/flask/app.py:1761]
Traceback (most recent call last):
  File "/Users/huiji/Desktop/mine/python/microblog/venv/lib/python3.7/site-packages/flask/app.py", line 2292, in wsgi_app
    response = self.full_dispatch_request()
  File "/Users/huiji/Desktop/mine/python/microblog/venv/lib/python3.7/site-packages/flask/app.py", line 1815, in full_dispatch_request
    rv = self.handle_user_exception(e)
  File "/Users/huiji/Desktop/mine/python/microblog/venv/lib/python3.7/site-packages/flask/app.py", line 1718, in handle_user_exception
    reraise(exc_type, exc_value, tb)
  File "/Users/huiji/Desktop/mine/python/microblog/venv/lib/python3.7/site-packages/flask/_compat.py", line 35, in reraise
    raise value
  File "/Users/huiji/Desktop/mine/python/microblog/venv/lib/python3.7/site-packages/flask/app.py", line 1813, in full_dispatch_request
    rv = self.dispatch_request()
  File "/Users/huiji/Desktop/mine/python/microblog/venv/lib/python3.7/site-packages/flask/app.py", line 1799, in dispatch_request
    return self.view_functions[rule.endpoint](**req.view_args)
  File "/Users/huiji/Desktop/mine/python/microblog/app/routes.py", line 151, in reset_password_request
    send_password_reset_email(user)
  File "/Users/huiji/Desktop/mine/python/microblog/app/email.py", line 19, in send_password_reset_email
    token = user.get_reset_password_token()
  File "/Users/huiji/Desktop/mine/python/microblog/app/models.py", line 61, in get_reset_password_token
    app.config['SECRET_KEY'], algorithms='HS256').decode('utf-8')
TypeError: encode() got an unexpected keyword argument 'algorithms'
2018-11-21 19:24:30,606 INFO: Microblog startup [in /Users/huiji/Desktop/mine/python/microblog/app/__init__.py:47]
2018-11-21 19:24:58,840 ERROR: Exception on /reset_password/eyJ0eXAiOiJKV1QiLCJhbGciOiJIUzI1NiJ9.eyJyZXNldF9wYXNzd29yZCI6MSwiZXhwIjoxNTQyODAwMDgwLjE0NTg5MTJ9.q3z_hoWU7Bm2zEdcf5DtdMhp8UubmqbtLaGkhid5nYA [GET] [in /Users/huiji/Desktop/mine/python/microblog/venv/lib/python3.7/site-packages/flask/app.py:1761]
Traceback (most recent call last):
  File "/Users/huiji/Desktop/mine/python/microblog/venv/lib/python3.7/site-packages/flask/app.py", line 2292, in wsgi_app
    response = self.full_dispatch_request()
  File "/Users/huiji/Desktop/mine/python/microblog/venv/lib/python3.7/site-packages/flask/app.py", line 1815, in full_dispatch_request
    rv = self.handle_user_exception(e)
  File "/Users/huiji/Desktop/mine/python/microblog/venv/lib/python3.7/site-packages/flask/app.py", line 1718, in handle_user_exception
    reraise(exc_type, exc_value, tb)
  File "/Users/huiji/Desktop/mine/python/microblog/venv/lib/python3.7/site-packages/flask/_compat.py", line 35, in reraise
    raise value
  File "/Users/huiji/Desktop/mine/python/microblog/venv/lib/python3.7/site-packages/flask/app.py", line 1813, in full_dispatch_request
    rv = self.dispatch_request()
  File "/Users/huiji/Desktop/mine/python/microblog/venv/lib/python3.7/site-packages/flask/app.py", line 1799, in dispatch_request
    return self.view_functions[rule.endpoint](**req.view_args)
  File "/Users/huiji/Desktop/mine/python/microblog/app/routes.py", line 159, in reset_password
    if current_user.is_authenticared:
  File "/Users/huiji/Desktop/mine/python/microblog/venv/lib/python3.7/site-packages/werkzeug/local.py", line 347, in __getattr__
    return getattr(self._get_current_object(), name)
AttributeError: 'AnonymousUserMixin' object has no attribute 'is_authenticared'
2018-11-21 19:25:36,788 INFO: Microblog startup [in /Users/huiji/Desktop/mine/python/microblog/app/__init__.py:47]
